Workbook

Sheet Read Me
A1: Off Hours: Unit Economics Model
A2: A first-pass model for one Boston location plus a multi-location rollout. Every number is editable.
A4: How to use
A5: 1. Change only the blue numbers on the Inputs tab. Yellow cells are the assumptions that move the result most.
A6: B2B: set the share of members paid by employers (teams, clinics, hospitals) on Inputs. Employer seats are cheaper but used less, which lowers massage and coffee costs.
A7: 2. Unit Economics shows one location at steady state: monthly P&L, break-even members, and capacity checks.
A8: 3. 36-Month Ramp shows the first location month by month, from opening day to payback.
A9: 4. Sensitivity shows monthly profit across price, member count, and included massage minutes.
A10: 6. Funding Plan shows how much cash Location 1 needs and one way to stack your $50K, prepayments, an SBA loan and investors.
A11: 5. Rollout shows the company view (many locations + HQ costs) and how much capital you would need to raise.
A13: Color legend
A14: Blue text = input you can change
... A22: A massage establishment license from the MA Board of Registration of Massage Therapy is assumed. See Sources & Notes.

Sheet Inputs
A1: Inputs (edit blue cells)
A3: Input | B3: Value | C3: Source / note
A5: Pricing and members
A6: Monthly membership price | B6: 150 | C6: From you: $150/month
A7: Extra 15-minute chair massage: list price | B7: 40 | C7: Assumption: list price for non-included massages
A8: Member discount on extra massages | B8: 0.1 | C8: From you: members get 10% off additional massages
A9: Extra massages bought per active member per month | B9: 0.5 | C9: Assumption: about one extra massage every two months
A10: Other add-on revenue per active member (guest passes, retail tea) | B10: 5 | C10: Assumption
A11: Add-on revenue per active member (calculated) | B11: =Inputs!$B$10+Inputs!$B$9*Inputs!$B$7*(1-Inputs!$B$8) -> 23 | C11: Formula: other add-ons + extra massages at the member price
A12: Card processing fees (% of revenue) | B12: 0.03 | C12: Assumption: typical Stripe/Square rate
A13: Steady-state members per location | B13: 550 | C13: Assumption: e.g. 330 consumers + 220 employer seats (~22 companies x 10). The single most important number in the model
A14: Members on opening day | B14: 150 | C14: Assumption: 100 of your 250+ waitlist sign-ups join, plus 50 employer seats (e.g. 5 of your 10 companies x 10 seats)
A15: New members joining per month (during ramp) | B15: 40 | C15: Assumption
A16: Monthly member churn | B16: 0.04 | C16: Assumption: boutique fitness memberships commonly lose 3 to 5% a month
A18: B2B: teams and healthcare (employer-paid seats)
A19: Share of members paid for by an employer | B19: 0.4 | C19: Assumption. 0% = consumer only. Employers sign annual contracts for seats
A20: Employer seat price per month | B20: 140 | C20: Assumption: modest discount for annual contracts. Below ~$135 a seat earns less than a consumer member
A21: Employer seat usage vs a self-paying member | B21: 0.65 | C21: Assumption. Employer-paid perks are used less: a UK study found ~24% of corporate gym memberships never used (4global DataHub, 2018)
A22: Employer seat churn per month | B22: 0.015 | C22: Assumption: annual contracts churn far less than individual members
A23: B2B sales cost (% of employer revenue) | B23: 0.1 | C23: Assumption: commission for a salesperson, broker, or benefits platform fee
A25: Member usage
A26: Lounge visits per member per month | B26: 6 | C26: Assumption. Daily is the brand promise, but most members will come 1 to 2x a week
A27: Average stay (hours) | B27: 1.5 | C27: Assumption
A28: Peak-hour factor (busiest hour vs average hour) | B28: 2.5 | C28: Assumption: lunch and after-work rush
A29: Open hours per day | B29: 14 | C29: Assumption: 7am to 9pm
A30: Open days per month | B30: 30 | C30: Assumption: 7 days a week
A31: Massage minutes included per member per month | B31: 30 | C31: From you: two 15-minute chair massages a month
A32: Share of included massage minutes actually used | B32: 0.75 | C32: Assumption: not everyone uses all four
A33: Drinks per visit | B33: 1.2 | C33: Assumption
A34: Cost per drink (beans, milk, tea, cup) | B34: 1.1 | C34: Assumption
A35: Consumables per visit (linens, oils, snacks) | B35: 0.75 | C35: Assumption
A37: Massage staffing
A38: Therapist hourly pay | B38: 38 | C38: Boston-area median is $36.13/hr (BLS, May 2025, via WageDex). Set slightly above to recruit good people
A39: Payroll taxes and benefits (% of pay) | B39: 0.15 | C39: Assumption for part-time W-2 staff in MA (FICA, unemployment, PFML, workers comp)
A40: Therapist utilization (booked hours / paid hours) | B40: 0.75 | C40: Assumption: gaps between bookings and no-shows are paid time
A41: Paid hours per therapist per month | B41: 80 | C41: Assumption: part-time, about 20 hours a week
A42: Massage chair stations | B42: 3 | C42: Assumption: semi-private chair massage spaces
A43: Labor cost of extra massages per active member (calculated) | B43: =Inputs!$B$9*15/60/Inputs!$B$40*Inputs!$B$38*(1+Inputs!$B$39) -> 7.2833333 | C43: Formula: extra massages x 15 minutes, paid at therapist cost
A44: Target chair station occupancy | B44: 0.65 | C44: Assumption
A46: Space
...

Sheet Unit Economics
A1: One location at steady state (monthly)
A2: Members are set by 'Steady-state members per location' on Inputs.
A4: Members | B4: Monthly | C4: Per member
A5: Total members | B5: =Inputs!$B$13 -> 550
A6: Self-paying members | B6: =$B$5*(1-Inputs!$B$19) -> 330
A7: Employer-paid seats | B7: =$B$5*Inputs!$B$19 -> 220
A8: Active-member equivalents (employer seats count at their usage rate) | B8: =$B$6+$B$7*Inputs!$B$21 -> 473
A10: Revenue | B10: Monthly | C10: Per member
A11: Self-paying memberships | B11: =$B$6*Inputs!$B$6 -> 49500 | C11: =IF($B$5=0,0,B11/$B$5) -> 90
A12: Employer seat contracts | B12: =$B$7*Inputs!$B$20 -> 30800 | C12: =IF($B$5=0,0,B12/$B$5) -> 56
A13: Add-on revenue | B13: =$B$8*Inputs!$B$11 -> 10879 | C13: =IF($B$5=0,0,B13/$B$5) -> 19.78
A14: Total revenue | B14: =$B$11+$B$12+$B$13 -> 91179 | C14: =IF($B$5=0,0,B14/$B$5) -> 165.78
A16: Variable costs (scale with members) | B16: Monthly | C16: Per member
A17: Card fees (self-paying members and add-ons; employers pay by bank transfer) | B17: =($B$11+$B$13)*Inputs!$B$12 -> 1811.37 | C17: =IF($B$5=0,0,B17/$B$5) -> 3.2934
A18: B2B sales cost | B18: =$B$12*Inputs!$B$23 -> 3080 | C18: =IF($B$5=0,0,B18/$B$5) -> 5.6
A19: Massage therapist labor (included + extra massages) | B19: =$B$8*(Inputs!$B$31/60*Inputs!$B$32/Inputs!$B$40*Inputs!$B$38*(1+Inputs!$B$39)+Inputs!$B$43) -> 13780.067 | C19: =IF($B$5=0,0,B19/$B$5) -> 25.054667
A20: Coffee and tea | B20: =$B$8*Inputs!$B$26*Inputs!$B$33*Inputs!$B$34 -> 3746.16 | C20: =IF($B$5=0,0,B20/$B$5) -> 6.8112
A21: Consumables | B21: =$B$8*Inputs!$B$26*Inputs!$B$35 -> 2128.5 | C21: =IF($B$5=0,0,B21/$B$5) -> 3.87
A22: Total variable costs | B22: =SUM($B$17:$B$21) -> 24546.097 | C22: =IF($B$5=0,0,B22/$B$5) -> 44.629267
A23: Contribution after variable costs | B23: =$B$14-$B$22 -> 66632.903 | C23: =IF($B$5=0,0,B23/$B$5) -> 121.15073
A25: Fixed costs (same whether you have 200 or 500 members) | B25: Monthly | C25: Per member
A26: Rent (after the pilot period) | B26: =IF(Inputs!$B$49=2,MAX(Inputs!$B$51,$B$14*Inputs!$B$50),Inputs!$B$47*Inputs!$B$48/12) -> 13676.85 | C26: =IF($B$5=0,0,B26/$B$5) -> 24.867
A27: Part-time general manager (incl. taxes) | B27: =Inputs!$B$57*(1+Inputs!$B$39)/12 -> 4312.5 | C27: =IF($B$5=0,0,B27/$B$5) -> 7.8409091
A28: Hosts / front desk | B28: =Inputs!$B$29*Inputs!$B$30*Inputs!$B$61*Inputs!$B$60*(1+Inputs!$B$39) -> 10626 | C28: =IF($B$5=0,0,B28/$B$5) -> 19.32
A29: Ritual facilitators | B29: =Inputs!$B$62*Inputs!$B$63 -> 3750 | C29: =IF($B$5=0,0,B29/$B$5) -> 6.8181818
A30: Other operating costs | B30: =Inputs!$B$66+Inputs!$B$67+Inputs!$B$68+Inputs!$B$69+Inputs!$B$70+Inputs!$B$71+Inputs!$B$72 -> 13000 | C30: =IF($B$5=0,0,B30/$B$5) -> 23.636364
A31: Total fixed costs | B31: =SUM($B$26:$B$30) -> 45365.35 | C31: =IF($B$5=0,0,B31/$B$5) -> 82.482455
A33: Profit | B33: Monthly | C33: Per member
A34: Location profit before HQ costs ("4-wall EBITDA") | B34: =$B$23-$B$31 -> 21267.553 | C34: =IF($B$5=0,0,B34/$B$5) -> 38.668279
A35: 4-wall margin | B35: =IF($B$14=0,0,$B$34/$B$14) -> 0.23325057
A36: Annual 4-wall EBITDA | B36: =$B$34*12 -> 255210.64
A37: Your salary (incl. payroll taxes) | B37: =Inputs!$B$58*(1+Inputs!$B$39)/12 -> 11500
A38: Profit after paying you (one-location company) | B38: =$B$34-$B$37 -> 9767.5533
A39: Annual profit after paying you | B39: =$B$38*12 -> 117210.64
A41: Break-even | B41: Monthly | C41: Per member
A42: Massage labor per active member (incl. extra massages) | B42: =Inputs!$B$31/60*Inputs!$B$32/Inputs!$B$40*Inputs!$B$38*(1+Inputs!$B$39)+Inputs!$B$43 -> 29.133333
A43: Other variable cost per active member | B43: =Inputs!$B$26*(Inputs!$B$33*Inputs!$B$34+Inputs!$B$35) -> 12.42
A44: Contribution per self-paying member | B44: =(Inputs!$B$6+Inputs!$B$11)*(1-Inputs!$B$12)-$B$42-$B$43 -> 126.25667
A45: Contribution per employer seat | B45: =Inputs!$B$20*(1-Inputs!$B$23)+Inputs!$B$21*(Inputs!$B$11*(1-Inputs!$B$12)-$B$42-$B$43) -> 113.49183
A46: Blended contribution per member | B46: =(1-Inputs!$B$19)*$B$44+Inputs!$B$19*$B$45 -> 121.15073
...

Sheet 36-Month Ramp
A1: First location, month by month
A2: Month 0 = opening costs and your pre-opening salary. Rent uses the pilot rate for the pilot months. Members start at the opening-day number, add new members monthly (self-paying + employer seats, same mix as Inputs), lose blended churn, and cap at steady state.
A4: Month | B4: 0 | C4: 1 | D4: 2 | E4: 3 | F4: 4 | G4: 5 | H4: 6 | I4: 7 | J4: 8 | K4: 9 | L4: 10 | M4: 11 | N4: 12 | O4: 13 | P4: 14 | Q4: 15 | R4: 16 | S4: 17 | T4: 18 | U4: 19 | V4: 20 | W4: 21 | X4: 22 | Y4: 23 | Z4: 24 | AA4: 25 | AB4: 26 | AC4: 27 | AD4: 28 | AE4: 29 | AF4: 30 | AG4: 31 | AH4: 32 | AI4: 33 | AJ4: 34 | AK4: 35 | AL4: 36
A5: Members | B5: 0 | C5: =Inputs!$B$14 -> 150 | D5: =MIN(Inputs!$B$13,C5*(1-'Unit Economics'!$B$49)+Inputs!$B$15) -> 185.5 | E5: =MIN(Inputs!$B$13,D5*(1-'Unit Economics'!$B$49)+Inputs!$B$15) -> 219.935 | F5: =MIN(Inputs!$B$13,E5*(1-'Unit Economics'!$B$49)+Inputs!$B$15) -> 253.33695 | G5: =MIN(Inputs!$B$13,F5*(1-'Unit Economics'!$B$49)+Inputs!$B$15) -> 285.73684 | H5: =MIN(Inputs!$B$13,G5*(1-'Unit Economics'!$B$49)+Inputs!$B$15) -> 317.16474 | I5: =MIN(Inputs!$B$13,H5*(1-'Unit Economics'!$B$49)+Inputs!$B$15) -> 347.64979 | J5: =MIN(Inputs!$B$13,I5*(1-'Unit Economics'!$B$49)+Inputs!$B$15) -> 377.2203 | K5: =MIN(Inputs!$B$13,J5*(1-'Unit Economics'!$B$49)+Inputs!$B$15) -> 405.90369 | ... AL5: =MIN(Inputs!$B$13,AK5*(1-'Unit Economics'!$B$49)+Inputs!$B$15) -> 550
A6: Revenue | B6: 0 | C6: =C5*'Unit Economics'!$B$47 -> 24867 | D6: =D5*'Unit Economics'!$B$47 -> 30752.19 | E6: =E5*'Unit Economics'!$B$47 -> 36460.824 | F6: =F5*'Unit Economics'!$B$47 -> 41998.2 | G6: =G5*'Unit Economics'!$B$47 -> 47369.454 | H6: =H5*'Unit Economics'!$B$47 -> 52579.57 | I6: =I5*'Unit Economics'!$B$47 -> 57633.383 | J6: =J5*'Unit Economics'!$B$47 -> 62535.581 | ... AL6: =AL5*'Unit Economics'!$B$47 -> 91179
A7: Variable costs | B7: 0 | C7: =C5*'Unit Economics'!$B$48 -> 6694.39 | D7: =D5*'Unit Economics'!$B$48 -> 8278.729 | E7: =E5*'Unit Economics'!$B$48 -> 9815.5378 | F7: =F5*'Unit Economics'!$B$48 -> 11306.242 | G7: =G5*'Unit Economics'!$B$48 -> 12752.226 | H7: =H5*'Unit Economics'!$B$48 -> 14154.83 | I7: =I5*'Unit Economics'!$B$48 -> 15515.355 | J7: =J5*'Unit Economics'!$B$48 -> 16835.065 | ... AL7: =AL5*'Unit Economics'!$B$48 -> 24546.097
A8: Rent | B8: 0 | C8: =IF(C4<=Inputs!$B$52,Inputs!$B$53,IF(Inputs!$B$49=2,MAX(Inputs!$B$51,C6*Inputs!$B$50),Inputs!$B$47*Inputs!$B$48/12)) -> 3000 | D8: =IF(D4<=Inputs!$B$52,Inputs!$B$53,IF(Inputs!$B$49=2,MAX(Inputs!$B$51,D6*Inputs!$B$50),Inputs!$B$47*Inputs!$B$48/12)) -> 3000 | E8: =IF(E4<=Inputs!$B$52,Inputs!$B$53,IF(Inputs!$B$49=2,MAX(Inputs!$B$51,E6*Inputs!$B$50),Inputs!$B$47*Inputs!$B$48/12)) -> 3000 | F8: =IF(F4<=Inputs!$B$52,Inputs!$B$53,IF(Inputs!$B$49=2,MAX(Inputs!$B$51,F6*Inputs!$B$50),Inputs!$B$47*Inputs!$B$48/12)) -> 3000 | G8: =IF(G4<=Inputs!$B$52,Inputs!$B$53,IF(Inputs!$B$49=2,MAX(Inputs!$B$51,G6*Inputs!$B$50),Inputs!$B$47*Inputs!$B$48/12)) -> 3000 | H8: =IF(H4<=Inputs!$B$52,Inputs!$B$53,IF(Inputs!$B$49=2,MAX(Inputs!$B$51,H6*Inputs!$B$50),Inputs!$B$47*Inputs!$B$48/12)) -> 3000 | I8: =IF(I4<=Inputs!$B$52,Inputs!$B$53,IF(Inputs!$B$49=2,MAX(Inputs!$B$51,I6*Inputs!$B$50),Inputs!$B$47*Inputs!$B$48/12)) -> 8645.0074 | J8: =IF(J4<=Inputs!$B$52,Inputs!$B$53,IF(Inputs!$B$49=2,MAX(Inputs!$B$51,J6*Inputs!$B$50),Inputs!$B$47*Inputs!$B$48/12)) -> 9380.3372 | ... AL8: =IF(AL4<=Inputs!$B$52,Inputs!$B$53,IF(Inputs!$B$49=2,MAX(Inputs!$B$51,AL6*Inputs!$B$50),Inputs!$B$47*Inputs!$B$48/12)) -> 13676.85
A9: Other fixed costs | B9: 0 | C9: =('Unit Economics'!$B$31-'Unit Economics'!$B$26) -> 31688.5 | D9: =('Unit Economics'!$B$31-'Unit Economics'!$B$26) -> 31688.5 | E9: =('Unit Economics'!$B$31-'Unit Economics'!$B$26) -> 31688.5 | F9: =('Unit Economics'!$B$31-'Unit Economics'!$B$26) -> 31688.5 | G9: =('Unit Economics'!$B$31-'Unit Economics'!$B$26) -> 31688.5 | H9: =('Unit Economics'!$B$31-'Unit Economics'!$B$26) -> 31688.5 | I9: =('Unit Economics'!$B$31-'Unit Economics'!$B$26) -> 31688.5 | J9: =('Unit Economics'!$B$31-'Unit Economics'!$B$26) -> 31688.5 | ... AL9: =('Unit Economics'!$B$31-'Unit Economics'!$B$26) -> 31688.5
A10: Location profit (4-wall) | B10: 0 | C10: =C6-C7-C8-C9 -> -16515.89 | D10: =D6-D7-D8-D9 -> -12215.039 | E10: =E6-E7-E8-E9 -> -8043.2135 | F10: =F6-F7-F8-F9 -> -3996.5427 | G10: =G6-G7-G8-G9 -> -71.272112 | H10: =H6-H7-H8-H9 -> 3736.2404 | I10: =I6-I7-I8-I9 -> 1784.5201 | J10: =J6-J7-J8-J9 -> 4631.6788 | ... AL10: =AL6-AL7-AL8-AL9 -> 21267.553
A11: Opening costs | B11: ='Unit Economics'!$B$69 -> 232000 | C11: 0 | D11: 0 | E11: 0 | F11: 0 | G11: 0 | H11: 0 | I11: 0 | J11: 0 | K11: 0 | L11: 0 | M11: 0 | N11: 0 | O11: 0 | P11: 0 | Q11: 0 | R11: 0 | S11: 0 | T11: 0 | U11: 0 | V11: 0 | W11: 0 | X11: 0 | Y11: 0 | Z11: 0 | AA11: 0 | AB11: 0 | AC11: 0 | AD11: 0 | AE11: 0 | AF11: 0 | AG11: 0 | AH11: 0 | AI11: 0 | AJ11: 0 | AK11: 0 | AL11: 0
A12: Net cash flow (after your salary) | B12: =B10-B11-B15 -> -278000 | C12: =C10-C11-C15 -> -28015.89 | D12: =D10-D11-D15 -> -23715.039 | E12: =E10-E11-E15 -> -19543.213 | F12: =F10-F11-F15 -> -15496.543 | G12: =G10-G11-G15 -> -11571.272 | H12: =H10-H11-H15 -> -7763.7596 | I12: =I10-I11-I15 -> -9715.4799 | ... AL12: =AL10-AL11-AL15 -> 9767.5533
A13: Cumulative cash | B13: =B12 -> -278000 | C13: =B13+C12 -> -306015.89 | D13: =C13+D12 -> -329730.93 | E13: =D13+E12 -> -349274.14 | F13: =E13+F12 -> -364770.69 | G13: =F13+G12 -> -376341.96 | H13: =G13+H12 -> -384105.72 | I13: =H13+I12 -> -393821.2 | J13: =I13+J12 -> -400689.52 | ... AL13: =AK13+AL12 -> -171831.04
A14: Payback month flag | C14: =IF(AND(C13>=0,B13<0),C4,"") | D14: =IF(AND(D13>=0,C13<0),D4,"") | E14: =IF(AND(E13>=0,D13<0),E4,"") | F14: =IF(AND(F13>=0,E13<0),F4,"") | G14: =IF(AND(G13>=0,F13<0),G4,"") | H14: =IF(AND(H13>=0,G13<0),H4,"") | I14: =IF(AND(I13>=0,H13<0),I4,"") | J14: =IF(AND(J13>=0,I13<0),J4,"") | ... AL14: =IF(AND(AL13>=0,AK13<0),AL4,"")
A15: Your salary (incl. taxes) | B15: =Inputs!$B$59*'Unit Economics'!$B$37 -> 46000 | C15: ='Unit Economics'!$B$37 -> 11500 | D15: ='Unit Economics'!$B$37 -> 11500 | E15: ='Unit Economics'!$B$37 -> 11500 | F15: ='Unit Economics'!$B$37 -> 11500 | G15: ='Unit Economics'!$B$37 -> 11500 | H15: ='Unit Economics'!$B$37 -> 11500 | I15: ='Unit Economics'!$B$37 -> 11500 | J15: ='Unit Economics'!$B$37 -> 11500 | ... AL15: ='Unit Economics'!$B$37 -> 11500
A16: Payback month (cash back from opening costs and your salary) | B16: =IF(COUNT(C14:AL14)=0,"Beyond 36 months",MIN(C14:AL14)) -> Beyond 36 months
A17: Lowest cash point (most cash at risk) | B17: =MIN(B13:AL13) -> -406223.78
A18: Month-36 cumulative cash | B18: =AL13 -> -171831.04

Sheet Sensitivity
A1: Monthly 4-wall profit for one location
A2: Uses the fixed-lease rent and all other inputs from the Inputs tab. Green = profitable.
A4: Table 1: Members (down) x Self-paying price (across). B2B mix, seat price and massage minutes as on Inputs.
A5: Members \ Price | B5: 130 | C5: 150 | D5: 175 | E5: 195 | F5: 225
A6: 250 | B6: =$A6*((1-Inputs!$B$19)*((B$5+Inputs!$B$11)*(1-Inputs!$B$12)-Inputs!$B$31*(Inputs!$B$32/Inputs!$B$40*Inputs!$B$38*(1+Inputs!$B$39)/60)-('Unit Economics'!$B$43+Inputs!$B$43))+Inputs!$B$19*'Unit Economics'!$B$45)-'Unit Economics'!$B$50 -> -15310.817 | C6: =$A6*((1-Inputs!$B$19)*((C$5+Inputs!$B$11)*(1-Inputs!$B$12)-Inputs!$B$31*(Inputs!$B$32/Inputs!$B$40*Inputs!$B$38*(1+Inputs!$B$39)/60)-('Unit Economics'!$B$43+Inputs!$B$43))+Inputs!$B$19*'Unit Economics'!$B$45)-'Unit Economics'!$B$50 -> -12400.817 | D6: =$A6*((1-Inputs!$B$19)*((D$5+Inputs!$B$11)*(1-Inputs!$B$12)-Inputs!$B$31*(Inputs!$B$32/Inputs!$B$40*Inputs!$B$38*(1+Inputs!$B$39)/60)-('Unit Economics'!$B$43+Inputs!$B$43))+Inputs!$B$19*'Unit Economics'!$B$45)-'Unit Economics'!$B$50 -> -8763.3167 | E6: =$A6*((1-Inputs!$B$19)*((E$5+Inputs!$B$11)*(1-Inputs!$B$12)-Inputs!$B$31*(Inputs!$B$32/Inputs!$B$40*Inputs!$B$38*(1+Inputs!$B$39)/60)-('Unit Economics'!$B$43+Inputs!$B$43))+Inputs!$B$19*'Unit Economics'!$B$45)-'Unit Economics'!$B$50 -> -5853.3167 | F6: =$A6*((1-Inputs!$B$19)*((F$5+Inputs!$B$11)*(1-Inputs!$B$12)-Inputs!$B$31*(Inputs!$B$32/Inputs!$B$40*Inputs!$B$38*(1+Inputs!$B$39)/60)-('Unit Economics'!$B$43+Inputs!$B$43))+Inputs!$B$19*'Unit Economics'!$B$45)-'Unit Economics'!$B$50 -> -1488.3167
A7: 300 | B7: =$A7*((1-Inputs!$B$19)*((B$5+Inputs!$B$11)*(1-Inputs!$B$12)-Inputs!$B$31*(Inputs!$B$32/Inputs!$B$40*Inputs!$B$38*(1+Inputs!$B$39)/60)-('Unit Economics'!$B$43+Inputs!$B$43))+Inputs!$B$19*'Unit Economics'!$B$45)-'Unit Economics'!$B$50 -> -9835.28 | C7: =$A7*((1-Inputs!$B$19)*((C$5+Inputs!$B$11)*(1-Inputs!$B$12)-Inputs!$B$31*(Inputs!$B$32/Inputs!$B$40*Inputs!$B$38*(1+Inputs!$B$39)/60)-('Unit Economics'!$B$43+Inputs!$B$43))+Inputs!$B$19*'Unit Economics'!$B$45)-'Unit Economics'!$B$50 -> -6343.28 | D7: =$A7*((1-Inputs!$B$19)*((D$5+Inputs!$B$11)*(1-Inputs!$B$12)-Inputs!$B$31*(Inputs!$B$32/Inputs!$B$40*Inputs!$B$38*(1+Inputs!$B$39)/60)-('Unit Economics'!$B$43+Inputs!$B$43))+Inputs!$B$19*'Unit Economics'!$B$45)-'Unit Economics'!$B$50 -> -1978.28 | E7: =$A7*((1-Inputs!$B$19)*((E$5+Inputs!$B$11)*(1-Inputs!$B$12)-Inputs!$B$31*(Inputs!$B$32/Inputs!$B$40*Inputs!$B$38*(1+Inputs!$B$39)/60)-('Unit Economics'!$B$43+Inputs!$B$43))+Inputs!$B$19*'Unit Economics'!$B$45)-'Unit Economics'!$B$50 -> 1513.72 | F7: =$A7*((1-Inputs!$B$19)*((F$5+Inputs!$B$11)*(1-Inputs!$B$12)-Inputs!$B$31*(Inputs!$B$32/Inputs!$B$40*Inputs!$B$38*(1+Inputs!$B$39)/60)-('Unit Economics'!$B$43+Inputs!$B$43))+Inputs!$B$19*'Unit Economics'!$B$45)-'Unit Economics'!$B$50 -> 6751.72
A8: 350 | B8: =$A8*((1-Inputs!$B$19)*((B$5+Inputs!$B$11)*(1-Inputs!$B$12)-Inputs!$B$31*(Inputs!$B$32/Inputs!$B$40*Inputs!$B$38*(1+Inputs!$B$39)/60)-('Unit Economics'!$B$43+Inputs!$B$43))+Inputs!$B$19*'Unit Economics'!$B$45)-'Unit Economics'!$B$50 -> -4359.7433 | C8: =$A8*((1-Inputs!$B$19)*((C$5+Inputs!$B$11)*(1-Inputs!$B$12)-Inputs!$B$31*(Inputs!$B$32/Inputs!$B$40*Inputs!$B$38*(1+Inputs!$B$39)/60)-('Unit Economics'!$B$43+Inputs!$B$43))+Inputs!$B$19*'Unit Economics'!$B$45)-'Unit Economics'!$B$50 -> -285.74333 | D8: =$A8*((1-Inputs!$B$19)*((D$5+Inputs!$B$11)*(1-Inputs!$B$12)-Inputs!$B$31*(Inputs!$B$32/Inputs!$B$40*Inputs!$B$38*(1+Inputs!$B$39)/60)-('Unit Economics'!$B$43+Inputs!$B$43))+Inputs!$B$19*'Unit Economics'!$B$45)-'Unit Economics'!$B$50 -> 4806.7567 | E8: =$A8*((1-Inputs!$B$19)*((E$5+Inputs!$B$11)*(1-Inputs!$B$12)-Inputs!$B$31*(Inputs!$B$32/Inputs!$B$40*Inputs!$B$38*(1+Inputs!$B$39)/60)-('Unit Economics'!$B$43+Inputs!$B$43))+Inputs!$B$19*'Unit Economics'!$B$45)-'Unit Economics'!$B$50 -> 8880.7567 | F8: =$A8*((1-Inputs!$B$19)*((F$5+Inputs!$B$11)*(1-Inputs!$B$12)-Inputs!$B$31*(Inputs!$B$32/Inputs!$B$40*Inputs!$B$38*(1+Inputs!$B$39)/60)-('Unit Economics'!$B$43+Inputs!$B$43))+Inputs!$B$19*'Unit Economics'!$B$45)-'Unit Economics'!$B$50 -> 14991.757
A9: 400 | B9: =$A9*((1-Inputs!$B$19)*((B$5+Inputs!$B$11)*(1-Inputs!$B$12)-Inputs!$B$31*(Inputs!$B$32/Inputs!$B$40*Inputs!$B$38*(1+Inputs!$B$39)/60)-('Unit Economics'!$B$43+Inputs!$B$43))+Inputs!$B$19*'Unit Economics'!$B$45)-'Unit Economics'!$B$50 -> 1115.7933 | C9: =$A9*((1-Inputs!$B$19)*((C$5+Inputs!$B$11)*(1-Inputs!$B$12)-Inputs!$B$31*(Inputs!$B$32/Inputs!$B$40*Inputs!$B$38*(1+Inputs!$B$39)/60)-('Unit Economics'!$B$43+Inputs!$B$43))+Inputs!$B$19*'Unit Economics'!$B$45)-'Unit Economics'!$B$50 -> 5771.7933 | D9: =$A9*((1-Inputs!$B$19)*((D$5+Inputs!$B$11)*(1-Inputs!$B$12)-Inputs!$B$31*(Inputs!$B$32/Inputs!$B$40*Inputs!$B$38*(1+Inputs!$B$39)/60)-('Unit Economics'!$B$43+Inputs!$B$43))+Inputs!$B$19*'Unit Economics'!$B$45)-'Unit Economics'!$B$50 -> 11591.793 | E9: =$A9*((1-Inputs!$B$19)*((E$5+Inputs!$B$11)*(1-Inputs!$B$12)-Inputs!$B$31*(Inputs!$B$32/Inputs!$B$40*Inputs!$B$38*(1+Inputs!$B$39)/60)-('Unit Economics'!$B$43+Inputs!$B$43))+Inputs!$B$19*'Unit Economics'!$B$45)-'Unit Economics'!$B$50 -> 16247.793 | F9: =$A9*((1-Inputs!$B$19)*((F$5+Inputs!$B$11)*(1-Inputs!$B$12)-Inputs!$B$31*(Inputs!$B$32/Inputs!$B$40*Inputs!$B$38*(1+Inputs!$B$39)/60)-('Unit Economics'!$B$43+Inputs!$B$43))+Inputs!$B$19*'Unit Economics'!$B$45)-'Unit Economics'!$B$50 -> 23231.793
A10: 450 | B10: =$A10*((1-Inputs!$B$19)*((B$5+Inputs!$B$11)*(1-Inputs!$B$12)-Inputs!$B$31*(Inputs!$B$32/Inputs!$B$40*Inputs!$B$38*(1+Inputs!$B$39)/60)-('Unit Economics'!$B$43+Inputs!$B$43))+Inputs!$B$19*'Unit Economics'!$B$45)-'Unit Economics'!$B$50 -> 6591.33 | C10: =$A10*((1-Inputs!$B$19)*((C$5+Inputs!$B$11)*(1-Inputs!$B$12)-Inputs!$B$31*(Inputs!$B$32/Inputs!$B$40*Inputs!$B$38*(1+Inputs!$B$39)/60)-('Unit Economics'!$B$43+Inputs!$B$43))+Inputs!$B$19*'Unit Economics'!$B$45)-'Unit Economics'!$B$50 -> 11829.33 | D10: =$A10*((1-Inputs!$B$19)*((D$5+Inputs!$B$11)*(1-Inputs!$B$12)-Inputs!$B$31*(Inputs!$B$32/Inputs!$B$40*Inputs!$B$38*(1+Inputs!$B$39)/60)-('Unit Economics'!$B$43+Inputs!$B$43))+Inputs!$B$19*'Unit Economics'!$B$45)-'Unit Economics'!$B$50 -> 18376.83 | E10: =$A10*((1-Inputs!$B$19)*((E$5+Inputs!$B$11)*(1-Inputs!$B$12)-Inputs!$B$31*(Inputs!$B$32/Inputs!$B$40*Inputs!$B$38*(1+Inputs!$B$39)/60)-('Unit Economics'!$B$43+Inputs!$B$43))+Inputs!$B$19*'Unit Economics'!$B$45)-'Unit Economics'!$B$50 -> 23614.83 | F10: =$A10*((1-Inputs!$B$19)*((F$5+Inputs!$B$11)*(1-Inputs!$B$12)-Inputs!$B$31*(Inputs!$B$32/Inputs!$B$40*Inputs!$B$38*(1+Inputs!$B$39)/60)-('Unit Economics'!$B$43+Inputs!$B$43))+Inputs!$B$19*'Unit Economics'!$B$45)-'Unit Economics'!$B$50 -> 31471.83
A11: 500 | B11: =$A11*((1-Inputs!$B$19)*((B$5+Inputs!$B$11)*(1-Inputs!$B$12)-Inputs!$B$31*(Inputs!$B$32/Inputs!$B$40*Inputs!$B$38*(1+Inputs!$B$39)/60)-('Unit Economics'!$B$43+Inputs!$B$43))+Inputs!$B$19*'Unit Economics'!$B$45)-'Unit Economics'!$B$50 -> 12066.867 | C11: =$A11*((1-Inputs!$B$19)*((C$5+Inputs!$B$11)*(1-Inputs!$B$12)-Inputs!$B$31*(Inputs!$B$32/Inputs!$B$40*Inputs!$B$38*(1+Inputs!$B$39)/60)-('Unit Economics'!$B$43+Inputs!$B$43))+Inputs!$B$19*'Unit Economics'!$B$45)-'Unit Economics'!$B$50 -> 17886.867 | D11: =$A11*((1-Inputs!$B$19)*((D$5+Inputs!$B$11)*(1-Inputs!$B$12)-Inputs!$B$31*(Inputs!$B$32/Inputs!$B$40*Inputs!$B$38*(1+Inputs!$B$39)/60)-('Unit Economics'!$B$43+Inputs!$B$43))+Inputs!$B$19*'Unit Economics'!$B$45)-'Unit Economics'!$B$50 -> 25161.867 | E11: =$A11*((1-Inputs!$B$19)*((E$5+Inputs!$B$11)*(1-Inputs!$B$12)-Inputs!$B$31*(Inputs!$B$32/Inputs!$B$40*Inputs!$B$38*(1+Inputs!$B$39)/60)-('Unit Economics'!$B$43+Inputs!$B$43))+Inputs!$B$19*'Unit Economics'!$B$45)-'Unit Economics'!$B$50 -> 30981.867 | F11: =$A11*((1-Inputs!$B$19)*((F$5+Inputs!$B$11)*(1-Inputs!$B$12)-Inputs!$B$31*(Inputs!$B$32/Inputs!$B$40*Inputs!$B$38*(1+Inputs!$B$39)/60)-('Unit Economics'!$B$43+Inputs!$B$43))+Inputs!$B$19*'Unit Economics'!$B$45)-'Unit Economics'!$B$50 -> 39711.867
A12: 550 | B12: =$A12*((1-Inputs!$B$19)*((B$5+Inputs!$B$11)*(1-Inputs!$B$12)-Inputs!$B$31*(Inputs!$B$32/Inputs!$B$40*Inputs!$B$38*(1+Inputs!$B$39)/60)-('Unit Economics'!$B$43+Inputs!$B$43))+Inputs!$B$19*'Unit Economics'!$B$45)-'Unit Economics'!$B$50 -> 17542.403 | C12: =$A12*((1-Inputs!$B$19)*((C$5+Inputs!$B$11)*(1-Inputs!$B$12)-Inputs!$B$31*(Inputs!$B$32/Inputs!$B$40*Inputs!$B$38*(1+Inputs!$B$39)/60)-('Unit Economics'!$B$43+Inputs!$B$43))+Inputs!$B$19*'Unit Economics'!$B$45)-'Unit Economics'!$B$50 -> 23944.403 | D12: =$A12*((1-Inputs!$B$19)*((D$5+Inputs!$B$11)*(1-Inputs!$B$12)-Inputs!$B$31*(Inputs!$B$32/Inputs!$B$40*Inputs!$B$38*(1+Inputs!$B$39)/60)-('Unit Economics'!$B$43+Inputs!$B$43))+Inputs!$B$19*'Unit Economics'!$B$45)-'Unit Economics'!$B$50 -> 31946.903 | E12: =$A12*((1-Inputs!$B$19)*((E$5+Inputs!$B$11)*(1-Inputs!$B$12)-Inputs!$B$31*(Inputs!$B$32/Inputs!$B$40*Inputs!$B$38*(1+Inputs!$B$39)/60)-('Unit Economics'!$B$43+Inputs!$B$43))+Inputs!$B$19*'Unit Economics'!$B$45)-'Unit Economics'!$B$50 -> 38348.903 | F12: =$A12*((1-Inputs!$B$19)*((F$5+Inputs!$B$11)*(1-Inputs!$B$12)-Inputs!$B$31*(Inputs!$B$32/Inputs!$B$40*Inputs!$B$38*(1+Inputs!$B$39)/60)-('Unit Economics'!$B$43+Inputs!$B$43))+Inputs!$B$19*'Unit Economics'!$B$45)-'Unit Economics'!$B$50 -> 47951.903
A13: 600 | B13: =$A13*((1-Inputs!$B$19)*((B$5+Inputs!$B$11)*(1-Inputs!$B$12)-Inputs!$B$31*(Inputs!$B$32/Inputs!$B$40*Inputs!$B$38*(1+Inputs!$B$39)/60)-('Unit Economics'!$B$43+Inputs!$B$43))+Inputs!$B$19*'Unit Economics'!$B$45)-'Unit Economics'!$B$50 -> 23017.94 | C13: =$A13*((1-Inputs!$B$19)*((C$5+Inputs!$B$11)*(1-Inputs!$B$12)-Inputs!$B$31*(Inputs!$B$32/Inputs!$B$40*Inputs!$B$38*(1+Inputs!$B$39)/60)-('Unit Economics'!$B$43+Inputs!$B$43))+Inputs!$B$19*'Unit Economics'!$B$45)-'Unit Economics'!$B$50 -> 30001.94 | D13: =$A13*((1-Inputs!$B$19)*((D$5+Inputs!$B$11)*(1-Inputs!$B$12)-Inputs!$B$31*(Inputs!$B$32/Inputs!$B$40*Inputs!$B$38*(1+Inputs!$B$39)/60)-('Unit Economics'!$B$43+Inputs!$B$43))+Inputs!$B$19*'Unit Economics'!$B$45)-'Unit Economics'!$B$50 -> 38731.94 | E13: =$A13*((1-Inputs!$B$19)*((E$5+Inputs!$B$11)*(1-Inputs!$B$12)-Inputs!$B$31*(Inputs!$B$32/Inputs!$B$40*Inputs!$B$38*(1+Inputs!$B$39)/60)-('Unit Economics'!$B$43+Inputs!$B$43))+Inputs!$B$19*'Unit Economics'!$B$45)-'Unit Economics'!$B$50 -> 45715.94 | F13: =$A13*((1-Inputs!$B$19)*((F$5+Inputs!$B$11)*(1-Inputs!$B$12)-Inputs!$B$31*(Inputs!$B$32/Inputs!$B$40*Inputs!$B$38*(1+Inputs!$B$39)/60)-('Unit Economics'!$B$43+Inputs!$B$43))+Inputs!$B$19*'Unit Economics'!$B$45)-'Unit Economics'!$B$50 -> 56191.94
A14: 700 | B14: =$A14*((1-Inputs!$B$19)*((B$5+Inputs!$B$11)*(1-Inputs!$B$12)-Inputs!$B$31*(Inputs!$B$32/Inputs!$B$40*Inputs!$B$38*(1+Inputs!$B$39)/60)-('Unit Economics'!$B$43+Inputs!$B$43))+Inputs!$B$19*'Unit Economics'!$B$45)-'Unit Economics'!$B$50 -> 33969.013 | C14: =$A14*((1-Inputs!$B$19)*((C$5+Inputs!$B$11)*(1-Inputs!$B$12)-Inputs!$B$31*(Inputs!$B$32/Inputs!$B$40*Inputs!$B$38*(1+Inputs!$B$39)/60)-('Unit Economics'!$B$43+Inputs!$B$43))+Inputs!$B$19*'Unit Economics'!$B$45)-'Unit Economics'!$B$50 -> 42117.013 | D14: =$A14*((1-Inputs!$B$19)*((D$5+Inputs!$B$11)*(1-Inputs!$B$12)-Inputs!$B$31*(Inputs!$B$32/Inputs!$B$40*Inputs!$B$38*(1+Inputs!$B$39)/60)-('Unit Economics'!$B$43+Inputs!$B$43))+Inputs!$B$19*'Unit Economics'!$B$45)-'Unit Economics'!$B$50 -> 52302.013 | E14: =$A14*((1-Inputs!$B$19)*((E$5+Inputs!$B$11)*(1-Inputs!$B$12)-Inputs!$B$31*(Inputs!$B$32/Inputs!$B$40*Inputs!$B$38*(1+Inputs!$B$39)/60)-('Unit Economics'!$B$43+Inputs!$B$43))+Inputs!$B$19*'Unit Economics'!$B$45)-'Unit Economics'!$B$50 -> 60450.013 | F14: =$A14*((1-Inputs!$B$19)*((F$5+Inputs!$B$11)*(1-Inputs!$B$12)-Inputs!$B$31*(Inputs!$B$32/Inputs!$B$40*Inputs!$B$38*(1+Inputs!$B$39)/60)-('Unit Economics'!$B$43+Inputs!$B$43))+Inputs!$B$19*'Unit Economics'!$B$45)-'Unit Economics'!$B$50 -> 72672.013
A17: Table 2: Included massage minutes per month (down) x Self-paying price (across). Members and B2B mix as on Inputs.
A18: Massage min \ Price | B18: 130 | C18: 150 | D18: 175 | E18: 195 | F18: 225
A19: 0 | B19: =Inputs!$B$13*((1-Inputs!$B$19)*((B$18+Inputs!$B$11)*(1-Inputs!$B$12)-$A19*(Inputs!$B$32/Inputs!$B$40*Inputs!$B$38*(1+Inputs!$B$39)/60)-('Unit Economics'!$B$43+Inputs!$B$43))+Inputs!$B$19*(Inputs!$B$20*(1-Inputs!$B$23)+Inputs!$B$21*(Inputs!$B$11*(1-Inputs!$B$12)-$A19*(Inputs!$B$32/Inputs!$B$40*Inputs!$B$38*(1+Inputs!$B$39)/60)-('Unit Economics'!$B$43+Inputs!$B$43))))-'Unit Economics'!$B$50 -> 27877.453 | C19: =Inputs!$B$13*((1-Inputs!$B$19)*((C$18+Inputs!$B$11)*(1-Inputs!$B$12)-$A19*(Inputs!$B$32/Inputs!$B$40*Inputs!$B$38*(1+Inputs!$B$39)/60)-('Unit Economics'!$B$43+Inputs!$B$43))+Inputs!$B$19*(Inputs!$B$20*(1-Inputs!$B$23)+Inputs!$B$21*(Inputs!$B$11*(1-Inputs!$B$12)-$A19*(Inputs!$B$32/Inputs!$B$40*Inputs!$B$38*(1+Inputs!$B$39)/60)-('Unit Economics'!$B$43+Inputs!$B$43))))-'Unit Economics'!$B$50 -> 34279.453 | D19: =Inputs!$B$13*((1-Inputs!$B$19)*((D$18+Inputs!$B$11)*(1-Inputs!$B$12)-$A19*(Inputs!$B$32/Inputs!$B$40*Inputs!$B$38*(1+Inputs!$B$39)/60)-('Unit Economics'!$B$43+Inputs!$B$43))+Inputs!$B$19*(Inputs!$B$20*(1-Inputs!$B$23)+Inputs!$B$21*(Inputs!$B$11*(1-Inputs!$B$12)-$A19*(Inputs!$B$32/Inputs!$B$40*Inputs!$B$38*(1+Inputs!$B$39)/60)-('Unit Economics'!$B$43+Inputs!$B$43))))-'Unit Economics'!$B$50 -> 42281.953 | E19: =Inputs!$B$13*((1-Inputs!$B$19)*((E$18+Inputs!$B$11)*(1-Inputs!$B$12)-$A19*(Inputs!$B$32/Inputs!$B$40*Inputs!$B$38*(1+Inputs!$B$39)/60)-('Unit Economics'!$B$43+Inputs!$B$43))+Inputs!$B$19*(Inputs!$B$20*(1-Inputs!$B$23)+Inputs!$B$21*(Inputs!$B$11*(1-Inputs!$B$12)-$A19*(Inputs!$B$32/Inputs!$B$40*Inputs!$B$38*(1+Inputs!$B$39)/60)-('Unit Economics'!$B$43+Inputs!$B$43))))-'Unit Economics'!$B$50 -> 48683.953 | F19: =Inputs!$B$13*((1-Inputs!$B$19)*((F$18+Inputs!$B$11)*(1-Inputs!$B$12)-$A19*(Inputs!$B$32/Inputs!$B$40*Inputs!$B$38*(1+Inputs!$B$39)/60)-('Unit Economics'!$B$43+Inputs!$B$43))+Inputs!$B$19*(Inputs!$B$20*(1-Inputs!$B$23)+Inputs!$B$21*(Inputs!$B$11*(1-Inputs!$B$12)-$A19*(Inputs!$B$32/Inputs!$B$40*Inputs!$B$38*(1+Inputs!$B$39)/60)-('Unit Economics'!$B$43+Inputs!$B$43))))-'Unit Economics'!$B$50 -> 58286.953
A20: 30 | B20: =Inputs!$B$13*((1-Inputs!$B$19)*((B$18+Inputs!$B$11)*(1-Inputs!$B$12)-$A20*(Inputs!$B$32/Inputs!$B$40*Inputs!$B$38*(1+Inputs!$B$39)/60)-('Unit Economics'!$B$43+Inputs!$B$43))+Inputs!$B$19*(Inputs!$B$20*(1-Inputs!$B$23)+Inputs!$B$21*(Inputs!$B$11*(1-Inputs!$B$12)-$A20*(Inputs!$B$32/Inputs!$B$40*Inputs!$B$38*(1+Inputs!$B$39)/60)-('Unit Economics'!$B$43+Inputs!$B$43))))-'Unit Economics'!$B$50 -> 17542.403 | C20: =Inputs!$B$13*((1-Inputs!$B$19)*((C$18+Inputs!$B$11)*(1-Inputs!$B$12)-$A20*(Inputs!$B$32/Inputs!$B$40*Inputs!$B$38*(1+Inputs!$B$39)/60)-('Unit Economics'!$B$43+Inputs!$B$43))+Inputs!$B$19*(Inputs!$B$20*(1-Inputs!$B$23)+Inputs!$B$21*(Inputs!$B$11*(1-Inputs!$B$12)-$A20*(Inputs!$B$32/Inputs!$B$40*Inputs!$B$38*(1+Inputs!$B$39)/60)-('Unit Economics'!$B$43+Inputs!$B$43))))-'Unit Economics'!$B$50 -> 23944.403 | D20: =Inputs!$B$13*((1-Inputs!$B$19)*((D$18+Inputs!$B$11)*(1-Inputs!$B$12)-$A20*(Inputs!$B$32/Inputs!$B$40*Inputs!$B$38*(1+Inputs!$B$39)/60)-('Unit Economics'!$B$43+Inputs!$B$43))+Inputs!$B$19*(Inputs!$B$20*(1-Inputs!$B$23)+Inputs!$B$21*(Inputs!$B$11*(1-Inputs!$B$12)-$A20*(Inputs!$B$32/Inputs!$B$40*Inputs!$B$38*(1+Inputs!$B$39)/60)-('Unit Economics'!$B$43+Inputs!$B$43))))-'Unit Economics'!$B$50 -> 31946.903 | E20: =Inputs!$B$13*((1-Inputs!$B$19)*((E$18+Inputs!$B$11)*(1-Inputs!$B$12)-$A20*(Inputs!$B$32/Inputs!$B$40*Inputs!$B$38*(1+Inputs!$B$39)/60)-('Unit Economics'!$B$43+Inputs!$B$43))+Inputs!$B$19*(Inputs!$B$20*(1-Inputs!$B$23)+Inputs!$B$21*(Inputs!$B$11*(1-Inputs!$B$12)-$A20*(Inputs!$B$32/Inputs!$B$40*Inputs!$B$38*(1+Inputs!$B$39)/60)-('Unit Economics'!$B$43+Inputs!$B$43))))-'Unit Economics'!$B$50 -> 38348.903 | F20: =Inputs!$B$13*((1-Inputs!$B$19)*((F$18+Inputs!$B$11)*(1-Inputs!$B$12)-$A20*(Inputs!$B$32/Inputs!$B$40*Inputs!$B$38*(1+Inputs!$B$39)/60)-('Unit Economics'!$B$43+Inputs!$B$43))+Inputs!$B$19*(Inputs!$B$20*(1-Inputs!$B$23)+Inputs!$B$21*(Inputs!$B$11*(1-Inputs!$B$12)-$A20*(Inputs!$B$32/Inputs!$B$40*Inputs!$B$38*(1+Inputs!$B$39)/60)-('Unit Economics'!$B$43+Inputs!$B$43))))-'Unit Economics'!$B$50 -> 47951.903
A21: 45 | B21: =Inputs!$B$13*((1-Inputs!$B$19)*((B$18+Inputs!$B$11)*(1-Inputs!$B$12)-$A21*(Inputs!$B$32/Inputs!$B$40*Inputs!$B$38*(1+Inputs!$B$39)/60)-('Unit Economics'!$B$43+Inputs!$B$43))+Inputs!$B$19*(Inputs!$B$20*(1-Inputs!$B$23)+Inputs!$B$21*(Inputs!$B$11*(1-Inputs!$B$12)-$A21*(Inputs!$B$32/Inputs!$B$40*Inputs!$B$38*(1+Inputs!$B$39)/60)-('Unit Economics'!$B$43+Inputs!$B$43))))-'Unit Economics'!$B$50 -> 12374.878 | C21: =Inputs!$B$13*((1-Inputs!$B$19)*((C$18+Inputs!$B$11)*(1-Inputs!$B$12)-$A21*(Inputs!$B$32/Inputs!$B$40*Inputs!$B$38*(1+Inputs!$B$39)/60)-('Unit Economics'!$B$43+Inputs!$B$43))+Inputs!$B$19*(Inputs!$B$20*(1-Inputs!$B$23)+Inputs!$B$21*(Inputs!$B$11*(1-Inputs!$B$12)-$A21*(Inputs!$B$32/Inputs!$B$40*Inputs!$B$38*(1+Inputs!$B$39)/60)-('Unit Economics'!$B$43+Inputs!$B$43))))-'Unit Economics'!$B$50 -> 18776.878 | D21: =Inputs!$B$13*((1-Inputs!$B$19)*((D$18+Inputs!$B$11)*(1-Inputs!$B$12)-$A21*(Inputs!$B$32/Inputs!$B$40*Inputs!$B$38*(1+Inputs!$B$39)/60)-('Unit Economics'!$B$43+Inputs!$B$43))+Inputs!$B$19*(Inputs!$B$20*(1-Inputs!$B$23)+Inputs!$B$21*(Inputs!$B$11*(1-Inputs!$B$12)-$A21*(Inputs!$B$32/Inputs!$B$40*Inputs!$B$38*(1+Inputs!$B$39)/60)-('Unit Economics'!$B$43+Inputs!$B$43))))-'Unit Economics'!$B$50 -> 26779.378 | E21: =Inputs!$B$13*((1-Inputs!$B$19)*((E$18+Inputs!$B$11)*(1-Inputs!$B$12)-$A21*(Inputs!$B$32/Inputs!$B$40*Inputs!$B$38*(1+Inputs!$B$39)/60)-('Unit Economics'!$B$43+Inputs!$B$43))+Inputs!$B$19*(Inputs!$B$20*(1-Inputs!$B$23)+Inputs!$B$21*(Inputs!$B$11*(1-Inputs!$B$12)-$A21*(Inputs!$B$32/Inputs!$B$40*Inputs!$B$38*(1+Inputs!$B$39)/60)-('Unit Economics'!$B$43+Inputs!$B$43))))-'Unit Economics'!$B$50 -> 33181.378 | F21: =Inputs!$B$13*((1-Inputs!$B$19)*((F$18+Inputs!$B$11)*(1-Inputs!$B$12)-$A21*(Inputs!$B$32/Inputs!$B$40*Inputs!$B$38*(1+Inputs!$B$39)/60)-('Unit Economics'!$B$43+Inputs!$B$43))+Inputs!$B$19*(Inputs!$B$20*(1-Inputs!$B$23)+Inputs!$B$21*(Inputs!$B$11*(1-Inputs!$B$12)-$A21*(Inputs!$B$32/Inputs!$B$40*Inputs!$B$38*(1+Inputs!$B$39)/60)-('Unit Economics'!$B$43+Inputs!$B$43))))-'Unit Economics'!$B$50 -> 42784.378
A22: 60 | B22: =Inputs!$B$13*((1-Inputs!$B$19)*((B$18+Inputs!$B$11)*(1-Inputs!$B$12)-$A22*(Inputs!$B$32/Inputs!$B$40*Inputs!$B$38*(1+Inputs!$B$39)/60)-('Unit Economics'!$B$43+Inputs!$B$43))+Inputs!$B$19*(Inputs!$B$20*(1-Inputs!$B$23)+Inputs!$B$21*(Inputs!$B$11*(1-Inputs!$B$12)-$A22*(Inputs!$B$32/Inputs!$B$40*Inputs!$B$38*(1+Inputs!$B$39)/60)-('Unit Economics'!$B$43+Inputs!$B$43))))-'Unit Economics'!$B$50 -> 7207.3533 | C22: =Inputs!$B$13*((1-Inputs!$B$19)*((C$18+Inputs!$B$11)*(1-Inputs!$B$12)-$A22*(Inputs!$B$32/Inputs!$B$40*Inputs!$B$38*(1+Inputs!$B$39)/60)-('Unit Economics'!$B$43+Inputs!$B$43))+Inputs!$B$19*(Inputs!$B$20*(1-Inputs!$B$23)+Inputs!$B$21*(Inputs!$B$11*(1-Inputs!$B$12)-$A22*(Inputs!$B$32/Inputs!$B$40*Inputs!$B$38*(1+Inputs!$B$39)/60)-('Unit Economics'!$B$43+Inputs!$B$43))))-'Unit Economics'!$B$50 -> 13609.353 | D22: =Inputs!$B$13*((1-Inputs!$B$19)*((D$18+Inputs!$B$11)*(1-Inputs!$B$12)-$A22*(Inputs!$B$32/Inputs!$B$40*Inputs!$B$38*(1+Inputs!$B$39)/60)-('Unit Economics'!$B$43+Inputs!$B$43))+Inputs!$B$19*(Inputs!$B$20*(1-Inputs!$B$23)+Inputs!$B$21*(Inputs!$B$11*(1-Inputs!$B$12)-$A22*(Inputs!$B$32/Inputs!$B$40*Inputs!$B$38*(1+Inputs!$B$39)/60)-('Unit Economics'!$B$43+Inputs!$B$43))))-'Unit Economics'!$B$50 -> 21611.853 | E22: =Inputs!$B$13*((1-Inputs!$B$19)*((E$18+Inputs!$B$11)*(1-Inputs!$B$12)-$A22*(Inputs!$B$32/Inputs!$B$40*Inputs!$B$38*(1+Inputs!$B$39)/60)-('Unit Economics'!$B$43+Inputs!$B$43))+Inputs!$B$19*(Inputs!$B$20*(1-Inputs!$B$23)+Inputs!$B$21*(Inputs!$B$11*(1-Inputs!$B$12)-$A22*(Inputs!$B$32/Inputs!$B$40*Inputs!$B$38*(1+Inputs!$B$39)/60)-('Unit Economics'!$B$43+Inputs!$B$43))))-'Unit Economics'!$B$50 -> 28013.853 | F22: =Inputs!$B$13*((1-Inputs!$B$19)*((F$18+Inputs!$B$11)*(1-Inputs!$B$12)-$A22*(Inputs!$B$32/Inputs!$B$40*Inputs!$B$38*(1+Inputs!$B$39)/60)-('Unit Economics'!$B$43+Inputs!$B$43))+Inputs!$B$19*(Inputs!$B$20*(1-Inputs!$B$23)+Inputs!$B$21*(Inputs!$B$11*(1-Inputs!$B$12)-$A22*(Inputs!$B$32/Inputs!$B$40*Inputs!$B$38*(1+Inputs!$B$39)/60)-('Unit Economics'!$B$43+Inputs!$B$43))))-'Unit Economics'!$B$50 -> 37616.853
A23: 90 | B23: =Inputs!$B$13*((1-Inputs!$B$19)*((B$18+Inputs!$B$11)*(1-Inputs!$B$12)-$A23*(Inputs!$B$32/Inputs!$B$40*Inputs!$B$38*(1+Inputs!$B$39)/60)-('Unit Economics'!$B$43+Inputs!$B$43))+Inputs!$B$19*(Inputs!$B$20*(1-Inputs!$B$23)+Inputs!$B$21*(Inputs!$B$11*(1-Inputs!$B$12)-$A23*(Inputs!$B$32/Inputs!$B$40*Inputs!$B$38*(1+Inputs!$B$39)/60)-('Unit Economics'!$B$43+Inputs!$B$43))))-'Unit Economics'!$B$50 -> -3127.6967 | C23: =Inputs!$B$13*((1-Inputs!$B$19)*((C$18+Inputs!$B$11)*(1-Inputs!$B$12)-$A23*(Inputs!$B$32/Inputs!$B$40*Inputs!$B$38*(1+Inputs!$B$39)/60)-('Unit Economics'!$B$43+Inputs!$B$43))+Inputs!$B$19*(Inputs!$B$20*(1-Inputs!$B$23)+Inputs!$B$21*(Inputs!$B$11*(1-Inputs!$B$12)-$A23*(Inputs!$B$32/Inputs!$B$40*Inputs!$B$38*(1+Inputs!$B$39)/60)-('Unit Economics'!$B$43+Inputs!$B$43))))-'Unit Economics'!$B$50 -> 3274.3033 | D23: =Inputs!$B$13*((1-Inputs!$B$19)*((D$18+Inputs!$B$11)*(1-Inputs!$B$12)-$A23*(Inputs!$B$32/Inputs!$B$40*Inputs!$B$38*(1+Inputs!$B$39)/60)-('Unit Economics'!$B$43+Inputs!$B$43))+Inputs!$B$19*(Inputs!$B$20*(1-Inputs!$B$23)+Inputs!$B$21*(Inputs!$B$11*(1-Inputs!$B$12)-$A23*(Inputs!$B$32/Inputs!$B$40*Inputs!$B$38*(1+Inputs!$B$39)/60)-('Unit Economics'!$B$43+Inputs!$B$43))))-'Unit Economics'!$B$50 -> 11276.803 | E23: =Inputs!$B$13*((1-Inputs!$B$19)*((E$18+Inputs!$B$11)*(1-Inputs!$B$12)-$A23*(Inputs!$B$32/Inputs!$B$40*Inputs!$B$38*(1+Inputs!$B$39)/60)-('Unit Economics'!$B$43+Inputs!$B$43))+Inputs!$B$19*(Inputs!$B$20*(1-Inputs!$B$23)+Inputs!$B$21*(Inputs!$B$11*(1-Inputs!$B$12)-$A23*(Inputs!$B$32/Inputs!$B$40*Inputs!$B$38*(1+Inputs!$B$39)/60)-('Unit Economics'!$B$43+Inputs!$B$43))))-'Unit Economics'!$B$50 -> 17678.803 | F23: =Inputs!$B$13*((1-Inputs!$B$19)*((F$18+Inputs!$B$11)*(1-Inputs!$B$12)-$A23*(Inputs!$B$32/Inputs!$B$40*Inputs!$B$38*(1+Inputs!$B$39)/60)-('Unit Economics'!$B$43+Inputs!$B$43))+Inputs!$B$19*(Inputs!$B$20*(1-Inputs!$B$23)+Inputs!$B$21*(Inputs!$B$11*(1-Inputs!$B$12)-$A23*(Inputs!$B$32/Inputs!$B$40*Inputs!$B$38*(1+Inputs!$B$39)/60)-('Unit Economics'!$B$43+Inputs!$B$43))))-'Unit Economics'!$B$50 -> 27281.803
A26: Table 3: Share of members paid by employers (down) x Employer seat price (across). Members, consumer price and massage minutes as on Inputs.
A27: B2B share \ Seat price | B27: 100 | C27: 115 | D27: 125 | E27: 140 | F27: 150
A28: 0 | B28: =Inputs!$B$13*((1-$A28)*'Unit Economics'!$B$44+$A28*(B$27*(1-Inputs!$B$23)+Inputs!$B$21*(Inputs!$B$11*(1-Inputs!$B$12)-'Unit Economics'!$B$42-'Unit Economics'!$B$43)))-'Unit Economics'!$B$50 -> 26752.667 | C28: =Inputs!$B$13*((1-$A28)*'Unit Economics'!$B$44+$A28*(C$27*(1-Inputs!$B$23)+Inputs!$B$21*(Inputs!$B$11*(1-Inputs!$B$12)-'Unit Economics'!$B$42-'Unit Economics'!$B$43)))-'Unit Economics'!$B$50 -> 26752.667 | D28: =Inputs!$B$13*((1-$A28)*'Unit Economics'!$B$44+$A28*(D$27*(1-Inputs!$B$23)+Inputs!$B$21*(Inputs!$B$11*(1-Inputs!$B$12)-'Unit Economics'!$B$42-'Unit Economics'!$B$43)))-'Unit Economics'!$B$50 -> 26752.667 | E28: =Inputs!$B$13*((1-$A28)*'Unit Economics'!$B$44+$A28*(E$27*(1-Inputs!$B$23)+Inputs!$B$21*(Inputs!$B$11*(1-Inputs!$B$12)-'Unit Economics'!$B$42-'Unit Economics'!$B$43)))-'Unit Economics'!$B$50 -> 26752.667 | F28: =Inputs!$B$13*((1-$A28)*'Unit Economics'!$B$44+$A28*(F$27*(1-Inputs!$B$23)+Inputs!$B$21*(Inputs!$B$11*(1-Inputs!$B$12)-'Unit Economics'!$B$42-'Unit Economics'!$B$43)))-'Unit Economics'!$B$50 -> 26752.667
A29: 0.2 | B29: =Inputs!$B$13*((1-$A29)*'Unit Economics'!$B$44+$A29*(B$27*(1-Inputs!$B$23)+Inputs!$B$21*(Inputs!$B$11*(1-Inputs!$B$12)-'Unit Economics'!$B$42-'Unit Economics'!$B$43)))-'Unit Economics'!$B$50 -> 21388.535 | C29: =Inputs!$B$13*((1-$A29)*'Unit Economics'!$B$44+$A29*(C$27*(1-Inputs!$B$23)+Inputs!$B$21*(Inputs!$B$11*(1-Inputs!$B$12)-'Unit Economics'!$B$42-'Unit Economics'!$B$43)))-'Unit Economics'!$B$50 -> 22873.535 | D29: =Inputs!$B$13*((1-$A29)*'Unit Economics'!$B$44+$A29*(D$27*(1-Inputs!$B$23)+Inputs!$B$21*(Inputs!$B$11*(1-Inputs!$B$12)-'Unit Economics'!$B$42-'Unit Economics'!$B$43)))-'Unit Economics'!$B$50 -> 23863.535 | E29: =Inputs!$B$13*((1-$A29)*'Unit Economics'!$B$44+$A29*(E$27*(1-Inputs!$B$23)+Inputs!$B$21*(Inputs!$B$11*(1-Inputs!$B$12)-'Unit Economics'!$B$42-'Unit Economics'!$B$43)))-'Unit Economics'!$B$50 -> 25348.535 | F29: =Inputs!$B$13*((1-$A29)*'Unit Economics'!$B$44+$A29*(F$27*(1-Inputs!$B$23)+Inputs!$B$21*(Inputs!$B$11*(1-Inputs!$B$12)-'Unit Economics'!$B$42-'Unit Economics'!$B$43)))-'Unit Economics'!$B$50 -> 26338.535
A30: 0.4 | B30: =Inputs!$B$13*((1-$A30)*'Unit Economics'!$B$44+$A30*(B$27*(1-Inputs!$B$23)+Inputs!$B$21*(Inputs!$B$11*(1-Inputs!$B$12)-'Unit Economics'!$B$42-'Unit Economics'!$B$43)))-'Unit Economics'!$B$50 -> 16024.403 | C30: =Inputs!$B$13*((1-$A30)*'Unit Economics'!$B$44+$A30*(C$27*(1-Inputs!$B$23)+Inputs!$B$21*(Inputs!$B$11*(1-Inputs!$B$12)-'Unit Economics'!$B$42-'Unit Economics'!$B$43)))-'Unit Economics'!$B$50 -> 18994.403 | D30: =Inputs!$B$13*((1-$A30)*'Unit Economics'!$B$44+$A30*(D$27*(1-Inputs!$B$23)+Inputs!$B$21*(Inputs!$B$11*(1-Inputs!$B$12)-'Unit Economics'!$B$42-'Unit Economics'!$B$43)))-'Unit Economics'!$B$50 -> 20974.403 | E30: =Inputs!$B$13*((1-$A30)*'Unit Economics'!$B$44+$A30*(E$27*(1-Inputs!$B$23)+Inputs!$B$21*(Inputs!$B$11*(1-Inputs!$B$12)-'Unit Economics'!$B$42-'Unit Economics'!$B$43)))-'Unit Economics'!$B$50 -> 23944.403 | F30: =Inputs!$B$13*((1-$A30)*'Unit Economics'!$B$44+$A30*(F$27*(1-Inputs!$B$23)+Inputs!$B$21*(Inputs!$B$11*(1-Inputs!$B$12)-'Unit Economics'!$B$42-'Unit Economics'!$B$43)))-'Unit Economics'!$B$50 -> 25924.403
A31: 0.6 | B31: =Inputs!$B$13*((1-$A31)*'Unit Economics'!$B$44+$A31*(B$27*(1-Inputs!$B$23)+Inputs!$B$21*(Inputs!$B$11*(1-Inputs!$B$12)-'Unit Economics'!$B$42-'Unit Economics'!$B$43)))-'Unit Economics'!$B$50 -> 10660.272 | C31: =Inputs!$B$13*((1-$A31)*'Unit Economics'!$B$44+$A31*(C$27*(1-Inputs!$B$23)+Inputs!$B$21*(Inputs!$B$11*(1-Inputs!$B$12)-'Unit Economics'!$B$42-'Unit Economics'!$B$43)))-'Unit Economics'!$B$50 -> 15115.272 | D31: =Inputs!$B$13*((1-$A31)*'Unit Economics'!$B$44+$A31*(D$27*(1-Inputs!$B$23)+Inputs!$B$21*(Inputs!$B$11*(1-Inputs!$B$12)-'Unit Economics'!$B$42-'Unit Economics'!$B$43)))-'Unit Economics'!$B$50 -> 18085.272 | E31: =Inputs!$B$13*((1-$A31)*'Unit Economics'!$B$44+$A31*(E$27*(1-Inputs!$B$23)+Inputs!$B$21*(Inputs!$B$11*(1-Inputs!$B$12)-'Unit Economics'!$B$42-'Unit Economics'!$B$43)))-'Unit Economics'!$B$50 -> 22540.272 | F31: =Inputs!$B$13*((1-$A31)*'Unit Economics'!$B$44+$A31*(F$27*(1-Inputs!$B$23)+Inputs!$B$21*(Inputs!$B$11*(1-Inputs!$B$12)-'Unit Economics'!$B$42-'Unit Economics'!$B$43)))-'Unit Economics'!$B$50 -> 25510.272
A32: 0.8 | B32: =Inputs!$B$13*((1-$A32)*'Unit Economics'!$B$44+$A32*(B$27*(1-Inputs!$B$23)+Inputs!$B$21*(Inputs!$B$11*(1-Inputs!$B$12)-'Unit Economics'!$B$42-'Unit Economics'!$B$43)))-'Unit Economics'!$B$50 -> 5296.14 | C32: =Inputs!$B$13*((1-$A32)*'Unit Economics'!$B$44+$A32*(C$27*(1-Inputs!$B$23)+Inputs!$B$21*(Inputs!$B$11*(1-Inputs!$B$12)-'Unit Economics'!$B$42-'Unit Economics'!$B$43)))-'Unit Economics'!$B$50 -> 11236.14 | D32: =Inputs!$B$13*((1-$A32)*'Unit Economics'!$B$44+$A32*(D$27*(1-Inputs!$B$23)+Inputs!$B$21*(Inputs!$B$11*(1-Inputs!$B$12)-'Unit Economics'!$B$42-'Unit Economics'!$B$43)))-'Unit Economics'!$B$50 -> 15196.14 | E32: =Inputs!$B$13*((1-$A32)*'Unit Economics'!$B$44+$A32*(E$27*(1-Inputs!$B$23)+Inputs!$B$21*(Inputs!$B$11*(1-Inputs!$B$12)-'Unit Economics'!$B$42-'Unit Economics'!$B$43)))-'Unit Economics'!$B$50 -> 21136.14 | F32: =Inputs!$B$13*((1-$A32)*'Unit Economics'!$B$44+$A32*(F$27*(1-Inputs!$B$23)+Inputs!$B$21*(Inputs!$B$11*(1-Inputs!$B$12)-'Unit Economics'!$B$42-'Unit Economics'!$B$43)))-'Unit Economics'!$B$50 -> 25096.14

Sheet Rollout
A1: Company view: multi-location rollout (annual)
A2: Each location follows the 36-Month Ramp: year 1 of a location = ramp months 1-12, year 2 = months 13-24, year 3+ = months 25-36. Opening costs land in the year a location opens.
B4: Year 1 | C4: Year 2 | D4: Year 3 | E4: Year 4 | F4: Year 5
A5: New locations opened (in their first year) | B5: =Inputs!B82 -> 1 | C5: =Inputs!C82 -> 1 | D5: =Inputs!D82 -> 2 | E5: =Inputs!E82 -> 4 | F5: =Inputs!F82 -> 6
A6: Locations in their second year | B6: =0 -> 0 | C6: =B5 -> 1 | D6: =C5 -> 1 | E6: =D5 -> 2 | F6: =E5 -> 4
A7: Locations in year 3 or later | B7: =0 -> 0 | C7: =B7+B6 -> 0 | D7: =C7+C6 -> 1 | E7: =D7+D6 -> 2 | F7: =E7+E6 -> 4
A8: Total locations open | B8: =B5+B6+B7 -> 1 | C8: =C5+C6+C7 -> 2 | D8: =D5+D6+D7 -> 4 | E8: =E5+E6+E7 -> 8 | F8: =F5+F6+F7 -> 14
A9: Revenue | B9: =B5*SUM('36-Month Ramp'!C6:N6)+B6*SUM('36-Month Ramp'!O6:Z6)+B7*SUM('36-Month Ramp'!AA6:AL6) -> 650484.58 | C9: =C5*SUM('36-Month Ramp'!C6:N6)+C6*SUM('36-Month Ramp'!O6:Z6)+C7*SUM('36-Month Ramp'!AA6:AL6) -> 1736211.7 | D9: =D5*SUM('36-Month Ramp'!C6:N6)+D6*SUM('36-Month Ramp'!O6:Z6)+D7*SUM('36-Month Ramp'!AA6:AL6) -> 3480844.3 | E9: =E5*SUM('36-Month Ramp'!C6:N6)+E6*SUM('36-Month Ramp'!O6:Z6)+E7*SUM('36-Month Ramp'!AA6:AL6) -> 6961688.6 | F9: =F5*SUM('36-Month Ramp'!C6:N6)+F6*SUM('36-Month Ramp'!O6:Z6)+F7*SUM('36-Month Ramp'!AA6:AL6) -> 12622408
A10: Location profit (4-wall EBITDA) | B10: =B5*SUM('36-Month Ramp'!C10:N10)+B6*SUM('36-Month Ramp'!O10:Z10)+B7*SUM('36-Month Ramp'!AA10:AL10) -> 14638.467 | C10: =C5*SUM('36-Month Ramp'!C10:N10)+C6*SUM('36-Month Ramp'!O10:Z10)+C7*SUM('36-Month Ramp'!AA10:AL10) -> 264958.32 | D10: =D5*SUM('36-Month Ramp'!C10:N10)+D6*SUM('36-Month Ramp'!O10:Z10)+D7*SUM('36-Month Ramp'!AA10:AL10) -> 534807.43 | E10: =E5*SUM('36-Month Ramp'!C10:N10)+E6*SUM('36-Month Ramp'!O10:Z10)+E7*SUM('36-Month Ramp'!AA10:AL10) -> 1069614.9 | F10: =F5*SUM('36-Month Ramp'!C10:N10)+F6*SUM('36-Month Ramp'!O10:Z10)+F7*SUM('36-Month Ramp'!AA10:AL10) -> 2109952.8
A11: HQ overhead | B11: =-Inputs!B83 -> -150000 | C11: =-Inputs!C83 -> -400000 | D11: =-Inputs!D83 -> -800000 | E11: =-Inputs!E83 -> -1400000 | F11: =-Inputs!F83 -> -2200000
A12: Company EBITDA | B12: =B10+B11 -> -135361.53 | C12: =C10+C11 -> -135041.68 | D12: =D10+D11 -> -265192.57 | E12: =E10+E11 -> -330385.14 | F12: =F10+F11 -> -90047.206
A13: Opening investment | B13: =-B5*'Unit Economics'!$B$69 -> -232000 | C13: =-C5*'Unit Economics'!$B$69 -> -232000 | D13: =-D5*'Unit Economics'!$B$69 -> -464000 | E13: =-E5*'Unit Economics'!$B$69 -> -928000 | F13: =-F5*'Unit Economics'!$B$69 -> -1392000
A14: Free cash flow | B14: =B12+B13 -> -367361.53 | C14: =C12+C13 -> -367041.68 | D14: =D12+D13 -> -729192.57 | E14: =E12+E13 -> -1258385.1 | F14: =F12+F13 -> -1482047.2
A15: Cumulative cash | B15: =B14 -> -367361.53 | C15: =B15+C14 -> -734403.21 | D15: =C15+D14 -> -1463595.8 | E15: =D15+E14 -> -2721980.9 | F15: =E15+F14 -> -4204028.1
A17: Peak capital need (lowest cumulative cash, years 1-5) | B17: =-MIN(0,MIN(B15:F15)) -> 4204028.1
A18: Add a 20-30% buffer on top of this when deciding how much to raise.

Sheet Funding Plan
A1: Funding plan for Location 1 (sources and uses)
A2: Uses pull from the model. Change the blue cells under Sources. Investors/angels is the plug: whatever is left to raise.
A4: Uses: what the money pays for
A5: Buildout (net of landlord allowance) | B5: ='Unit Economics'!$B$66 -> 72000
A6: Furniture, fixtures, equipment | B6: ='Unit Economics'!$B$67 -> 90000
A7: Pre-opening | B7: ='Unit Economics'!$B$68 -> 70000
A8: Your salary and operating losses until the location covers itself | B8: =MAX(0,-'36-Month Ramp'!$B$17-'Unit Economics'!$B$69) -> 174223.78 | C8: Lowest cumulative cash on the 36-Month Ramp, minus opening costs. Includes your salary before and after opening
A9: Contingency (% of the above) | B9: 0.2 | C9: Assumption: buildouts almost always run over
A10: Contingency | B10: =SUM($B$5:$B$8)*$B$9 -> 81244.756
A11: Total cash needed | B11: =SUM($B$5:$B$8)+$B$10 -> 487468.54
A13: Sources: where the money comes from
A14: Your own cash | B14: 50000 | C14: From you
A15: Founding members who prepay | B15: 0 | C15: From you: no founding prepayments
A16: Months each founding member prepays | B16: 3 | C16: Assumption: e.g. 3 months up front to lock founding status
A17: Founding member prepayments | B17: =$B$15*$B$16*Inputs!$B$6 -> 0 | C17: Cash before opening. It is revenue pulled forward, so it lowers what you raise but you collect less later
A18: Companies that prepay | B18: 10 | C18: Your target: 10 companies
A19: Seats per company | B19: 10 | C19: Assumption
A20: Months each company prepays | B20: 0 | C20: Set to 0: interest is not a contract. Upside if companies pay quarterly in advance
A21: Employer prepayments | B21: =$B$18*$B$19*$B$20*Inputs!$B$20 -> 0
A22: SBA 7(a) loan | B22: 0 | C22: Set to 0: SBA requires an unlimited personal guarantee from every 20%+ owner (13 CFR 120.160), which you ruled out
A23: Investors / angels / friends and family (left to raise) | B23: =MAX(0,$B$11-$B$14-$B$17-$B$21-$B$22) -> 437468.54 | C23: Typically raised on a SAFE
A24: Total sources | B24: =$B$14+$B$17+$B$21+$B$22+$B$23 -> 487468.54
A26: Checks
A27: Equity (you + investors) as % of total cash needed | B27: =IF($B$11=0,0,($B$14+$B$23)/$B$11) -> 1 | C27: SBA lenders want at least 10%
A28: Meets the 10% SBA minimum? | B28: =IF($B$27>=0.1,"Yes","No") -> Yes
A29: SBA loan interest rate | B29: 0.105 | C29: Assumption: prime plus a spread; get a lender quote
A30: Loan term (years) | B30: 10 | C30: Assumption
A31: Annual loan payments | B31: =IF($B$22=0,0,-PMT($B$29,$B$30,$B$22)) -> 0
A32: Debt coverage (steady-state profit / loan payments) | B32: =IF($B$31=0,"No loan",'Unit Economics'!$B$36/$B$31) -> No loan | C32: Lenders usually want 1.25x or more

Sheet Sources & Notes
A1: Sources and notes
A3: Membership price and benefits: from you. $150/month, two 15-minute chair massages included, 10% member discount on extra massages. Location: Downtown Crossing / Park Street, revenue-share deal.
A4: Massage therapist pay: Boston-Cambridge-Newton median $36.13/hr, BLS May 2025 via WageDex. https://wagedex.com/jobs/massage-therapists/metro/boston-cambridge-newton-ma-nh
A5: Payscale Boston LMT average $35/hr. https://www.payscale.com/research/US/Job=Licensed_Massage_Therapist_(LMT)/Hourly_Rate/9d4bcf95/Boston-MA
A6: Boston retail rents: Back Bay $125-225/sf, Seaport $85-150/sf (Banker & Tradesman). https://bankerandtradesman.com/fidelity-invests-in-seaports-retail-reinvention
A7: MA worker classification (ABC test, prong B): https://www.mass.gov/news/ag-campbell-files-amicus-brief-urging-court-to-reverse-decision-in-massachusetts-worker-misclassification-case
A8: MA massage establishment licensing, 269 CMR 6.00: https://www.mass.gov/regulations/269-CMR-6-facility-licensure
A9: Landlord management agreements / revenue share (Industrious): https://www.wealthmanagement.com/wealth-management-industry-trends/office-landlords-consider-management-agreements-in-lieu-of-leases-for-co-working-operators
A10: Fabrik below-market flexible leases and Hines backing (CoStar): https://www.costar.com/article/1868835210/this-hines-backed-startup-offers-flexible-space-to-more-than-office-workers
A11: Corporate membership usage benchmark: ~24% of employer-provided gym memberships never used (4global DataHub, UK, 2018). https://ukactive.com/news/new-research-explores-value-of-employer-provided-gym-memberships/
A12: SBA 7(a) 10% equity injection for startups under SOP 50 10 8 (secondary summary; confirm with a lender): https://beancount.io/blog/2026/07/29/sba-sop-50-10-8-collateral-equity-injection-rules-guide
A13: MA chair-massage exemption from establishment licensure, 269 CMR 6.03(8): https://www.law.cornell.edu/regulations/massachusetts/269-CMR-6-03
A15: Everything not listed above is a planning assumption, labeled on the Inputs tab. Replace with real quotes as you get them.
